Workbook
Name FIELD: #REF!
Name FIELD: #REF!
Name FIELD: #REF!
Name FIELD: #REF!
Name FIELD: #REF!
Name FIELD: #REF!
Name FIELD: #REF!
Name Speeds: Tracking!#REF!

Sheet ToDo
B1: PLC | D1: HMI
A2: 1
A3: 2
A4: 3
A5: 4
A6: 5
A7: 6
A8: 7
A9: 8
A10: 9
A11: 10
A12: 11
A13: 12
... A31: 30
B33: Schematics/BOM
A35: 1 | B35: LASER ENCLOSURE
A36: 2 | B36: CABLES FOR CONTROL BUTTONS AND LAMPS
A37: 3 | B37: IN LINE SOCKETS FOR DUST EXTRACTION | D37: MOTION SCALING
A38: 4 | D38: 18849556 | E38: Units at the load
A39: 5 | D39: 100000 | E39: Motor revolutions
A40: 6 | D40: Rotation carriage
A41: 7 | D41: 23750 | E41: Units at the load
A42: 8 | D42: 10 | E42: Motor revolutions
A43: 9
A44: 10
A45: 11
A46: 12
A47: 13 | B47: JOB SPECIFIC
A49: 1
A50: 2
B53: PLC | D53: HMI
A54: 1 | B54: TRACK SIZE DATA - IMPLEMENT IN PROGRAM GENERATION | C54: 1 | D54: RUNTIME COMPLETION FOR ACCEL AND DECEL PARAMETERS
A55: 2 | B55: S16 OVERRIDE FOR CENTERING - ADD END CONDITION? | C55: 2
A56: 3 | B56: CREATE SIMULATION DATA TYPE | C56: 3 | D56: PORTRAIT BATCHING DISPLAY
A57: 4 | B57: SET OUTPUTS, E.G. SOL35LASER, ETC….. | C57: 4 | D57: BatchData Ln114 Remove Comments
A58: 5 | B58: WILL MAX REMAINING DISPLAY WORK? NO | C58: 5 | D58: Footpedal Start for Next and Confirm
A59: 6 | B59: PAUSE PROGRAMMING | C59: 6
A60: 7 | B60: INVERTER RESET PROGRAM | C60: 7
A61: 8 | B61: EPLCOMMS PROGRAM | C61: 8
A62: 9 | B62: Scale delays for washer exit. | C62: 9
...

Sheet IO
B2: Key | D2: Input | F2: Input | H2: Output | J2: Output | L2: DC Supply Only
A3: POWERLINK X20 PANEL RACK
B4: PS | D4: IP | F4: IP | H4: OP | J4: PD | L4: PD
A5: BIT | B5: ST1 | D5: ST2 | F5: ST3 | H5: ST4 | J5: ST5 | L5: ST6 | N5: BIT
A6: 01 | B6: X20 POWER SUPPLY MODULE | D6: =BRMem!B1 -> Control.Start | E6: 200 | F6: =BRMem!B13 -> MS9Vac1.Trip | G6: =E17+1 -> 212 | H6: =BRMem!E1 -> Control.Buzzer | I6: 600 | J6: X20 +24VDC POTENTIAL DISTRIBUTION | L6: X20 GND POTENTIAL DISTRIBUTION | N6: 01
A7: 02 | D7: =BRMem!B2 -> Control.Stop | E7: =E6+1 -> 201 | F7: =BRMem!B14 -> MS10Vac2.Trip | G7: =G6+1 -> 213 | H7: =BRMem!E2 -> Control.OnLmp1 | I7: =I6+1 -> 601 | N7: 02
A8: 03 | D8: =BRMem!B3 -> Control.EStop1 | E8: =E7+1 -> 202 | F8: =BRMem!B15 -> MS11Vac3.Trip | G8: =G7+1 -> 214 | H8: =BRMem!E3 -> 0 | I8: =I7+1 -> 602 | N8: 03
A9: 04 | D9: =BRMem!B4 -> 0 | E9: =E8+1 -> 203 | F9: =BRMem!B16 -> MS12Vac4.Trip | G9: =G8+1 -> 215 | H9: =BRMem!E4 -> 0 | I9: =I8+1 -> 603 | N9: 04
A10: 05 | D10: =BRMem!B5 -> MS1Belt1.Trip | E10: =E9+1 -> 204 | F10: =BRMem!B17 -> MS13Water1.Trip | G10: =G9+1 -> 216 | H10: =BRMem!E5 -> 0 | I10: =I9+1 -> 604 | N10: 05
A11: 06 | D11: =BRMem!B6 -> MS2Belt2.Trip | E11: =E10+1 -> 205 | F11: =BRMem!B18 -> MS14Water2.Trip | G11: =G10+1 -> 217 | H11: =BRMem!E6 -> 0 | I11: =I10+1 -> 605 | N11: 06
A12: 07 | D12: =BRMem!B7 -> MS3Belt3.Trip | E12: =E11+1 -> 206 | F12: =BRMem!B19 -> 0 | G12: =G11+1 -> 218 | H12: =BRMem!E7 -> 0 | I12: =I11+1 -> 606 | N12: 07
A13: 08 | D13: =BRMem!B8 -> MS4Belt4.Trip | E13: =E12+1 -> 207 | F13: =BRMem!B20 -> 0 | G13: =G12+1 -> 219 | H13: =BRMem!E8 -> Sol37Spray | I13: =I12+1 -> 607 | N13: 08
A14: 09 | D14: =BRMem!B9 -> MS5Belt5.Trip | E14: =E13+1 -> 208 | F14: =BRMem!B21 -> 0 | G14: =G13+1 -> 220 | H14: =BRMem!E9 -> Sol47Spray | I14: =I13+1 -> 608 | N14: 09
A15: 10 | D15: =BRMem!B10 -> MS6Belt6.Trip | E15: =E14+1 -> 209 | F15: =BRMem!B22 -> 0 | G15: =G14+1 -> 221 | H15: =BRMem!E10 -> Sol53Recirc | I15: =I14+1 -> 609 | N15: 10
A16: 11 | D16: =BRMem!B11 -> MS7Belt7.Trip | E16: =E15+1 -> 210 | F16: =BRMem!B23 -> 0 | G16: =G15+1 -> 222 | H16: =BRMem!E11 -> Sol24DG1B | I16: =I15+1 -> 610 | N16: 11
A17: 12 | D17: =BRMem!B12 -> MS8Belt8.Trip | E17: =E16+1 -> 211 | F17: =BRMem!B24 -> ClearBatch.In | G17: =G16+1 -> 223 | H17: =BRMem!E12 -> Filstar | I17: =I16+1 -> 611 | N17: 12
A18: 13 | N18: 13
A19: 14 | N19: 14
A20: 15 | N20: 15
A21: 16 | N21: 16
A22: NO | B22: =(B5) -> ST1 | D22: =(D5) -> ST2 | F22: =(F5) -> ST3 | H22: =H5 -> ST4 | J22: =J5 -> ST5 | L22: =(L5) -> ST6 | N22: NO
A24: POWERLINK X20 PANEL RACK
B25: PD | D25: OP | F25: BT
A26: BIT | B26: ST7 | D26: ST8 | F26: ST9 | N26: BIT
A27: 01 | B27: X20 GND POTENTIAL DISTRIBUTION | D27: =BRMem!E13 -> MS1Belt1 | E27: =I17+1 -> 612 | F27: X2X BUS TRANSMITTER | N27: 01
A28: 02 | D28: =BRMem!E14 -> MS2Belt2 | E28: =E27+1 -> 613 | N28: 02
A29: 03 | D29: =BRMem!E15 -> MS3Belt3 | E29: =E28+1 -> 614 | N29: 03
A30: 04 | D30: =BRMem!E16 -> MS4Belt4 | E30: =E29+1 -> 615 | N30: 04
A31: 05 | D31: =BRMem!E17 -> MS5Belt5 | E31: =E30+1 -> 616 | N31: 05
A32: 06 | D32: =BRMem!E18 -> MS6Belt6 | E32: =E31+1 -> 617 | N32: 06
A33: 07 | D33: =BRMem!E19 -> MS7Belt7 | E33: =E32+1 -> 618 | N33: 07
A34: 08 | D34: =BRMem!E20 -> MS8Belt8 | E34: =E33+1 -> 619 | N34: 08
A35: 09 | D35: =BRMem!E21 -> MS9Vac1 | E35: =E34+1 -> 620 | N35: 09
A36: 10 | D36: =BRMem!E22 -> MS10Vac2 | E36: =E35+1 -> 621 | N36: 10
A37: 11 | D37: =BRMem!E23 -> MS11Vac3 | E37: =E36+1 -> 622 | N37: 11
A38: 12 | D38: =BRMem!E24 -> MS12Vac4 | E38: =E37+1 -> 623 | N38: 12
A39: 13 | D39: =BRMem!E25 -> MS13Water1 | E39: =E38+1 -> 624 | N39: 13
A40: 14 | D40: =BRMem!E26 -> MS14Water2 | E40: =E39+1 -> 625 | N40: 14
A41: 15 | D41: =BRMem!E27 -> 0 | E41: =E40+1 -> 626 | N41: 15
A42: 16 | D42: =BRMem!E28 -> 0 | E42: =E41+1 -> 627 | N42: 16
...

Sheet BRMem
A1: X20 Panel Inputs | B1: Control.Start | C1: Control Start PB - NO | D1: X20 Panel Outputs | E1: Control.Buzzer | F1: Panel Buzzer | G1: X67 Field I/O | H1: S45Foot.In | I1: End Loading Start Footpedal | J1: 100 | K1: 10M
A2: ST2 | B2: Control.Stop | C2: Control Stop PB - NO | D2: ST4 | E2: Control.OnLmp1 | F2: Control Circuit On Indicator | G2: ST10 | H2: S1Photo.In | I2: CL1 Slow Photoelectric Switch | J2: 101 | K2: 2M
B3: Control.EStop1 | C3: Safety Relay - NC | G3: >CBL21 | H3: S2Photo.In | I3: CL1 End Photelectric switch | J3: 102 | K3: 2M
G4: >CBL41 | H4: S56Lever.In | I4: Laser Enable Lever Selector | J4: 103 | K4: 5M | L4: B10JB
B5: MS1Belt1.Trip | C5: Motor Starter 1 - Belt 1 Motor Trip | G5: RM | H5: S30Reed.In | I5: Pallet 1 Down Reed Switch | J5: 104 | K5: 2M
B6: MS2Belt2.Trip | C6: Motor Starter 2 - Belt 2 Motor Trip | G6: 1M | H6: S31Reed.In | I6: Pallet 1 Up Reed Switch | J6: 105 | K6: 2M
B7: MS3Belt3.Trip | C7: Motor Starter 3 - Belt 3 Motor Trip | H7: LaserBusy | I7: Laser Busy Input | J7: 106 | K7: 5M | L7: B10JB
B8: MS4Belt4.Trip | C8: Motor Starter 4 - Belt 4 Motor Trip | E8: Sol37Spray | F8: Solenoid Valve 37 Atomiser Spray | H8: LaserFire | I8: Laser Fire Output | J8: 107 | K8: 5M | L8: B10JB
B9: MS5Belt5.Trip | C9: Motor Starter 5 - Belt 5 Motor Trip | E9: Sol47Spray | F9: Solenoid Valve 47 Atomiser Spray 2 | H9: S100Reed.In | I9: Flip Up Arm 1/1 Down Reed Switch | J9: 108 | K9: 0M
B10: MS6Belt6.Trip | C10: Motor Starter 6 - Belt 6 Motor Trip | E10: Sol53Recirc | F10: Solenoid Valve 53 Recirculation | H10: Sol1Blt1 | I10: Solenoid Valve 1 Belt 1 | J10: 109 | K10: 0M
B11: MS7Belt7.Trip | C11: Motor Starter 7 - Belt 7 Motor Trip | E11: Sol24DG1B | F11: Solenoid Valve 24 Datum Gate 1 B | H11: Sol2Blt2 | I11: Solenoid Valve 2 Belt 2 | J11: 110 | K11: 0M
B12: MS8Belt8.Trip | C12: Motor Starter 8 - Belt 8 Motor Trip | E12: Filstar | F12: Filstar output | H12: Sol5Arm1 | I12: Solenoid Valve 5 Flip Up Arm 1 | J12: 111 | K12: 0M
A13: X20 Panel Inputs | B13: MS9Vac1.Trip | C13: Motor Starter 9 - Vacuum 1 Pump Trip | D13: X20 Panel Outputs | E13: MS1Belt1 | F13: Motor Starter 1 - Belt 1 Motor | H13: Sol6Arm2 | I13: Solenoid Valve 6 Flip Up Arm 2 | J13: 112 | K13: 0M
A14: ST3 | B14: MS10Vac2.Trip | C14: Motor Starter 10 - Vacuum 2 Pump Trip | D14: ST8 | E14: MS2Belt2 | F14: Motor Starter 2 - Belt 2 Motor | H14: Sol7Arm3 | I14: Solenoid Valve 7 Flip Up Arm 3 | J14: 113 | K14: 0M
B15: MS11Vac3.Trip | C15: Motor Starter 11 - Vacuum 3 Pump Trip | E15: MS3Belt3 | F15: Motor Starter 3 - Belt 3 Motor | H15: Sol8Arm4 | I15: Solenoid Valve 8 Flip Up Arm 4 | J15: 114 | K15: 0M
B16: MS12Vac4.Trip | C16: Motor Starter 12 - Vacuum 4 Pump Trip | E16: MS4Belt4 | F16: Motor Starter 4 - Belt 4 Motor | H16: Sol20DT1 | I16: Solenoid Valve 20 Detension 1 | J16: 115 | K16: 0M
B17: MS13Water1.Trip | C17: Motor Starter 13 - Water Tank 1 Pump Trip | E17: MS5Belt5 | F17: Motor Starter 5 - Belt 5 Motor | G17: X67 Field I/O | H17: S81Photo.In | I17: Servo 1 Rev Photoelectric Switch | J17: 116 | K17: 0M
B18: MS14Water2.Trip | C18: Motor Starter 14 - Water Tank 2 Pump Trip | E18: MS6Belt6 | F18: Motor Starter 6 - Belt 6 Motor | G18: ST11 | H18: S82Photo.In | I18: Servo 1 Centre 1 Photoelectric Switch | J18: 117 | K18: 0M
E19: MS7Belt7 | F19: Motor Starter 7 - Belt 7 Motor | G19: >CBL22 | H19: S83Photo.In | I19: Servo 1 Centre 2 Photoelectric Switch | J19: 118 | K19: 0M
E20: MS8Belt8 | F20: Motor Starter 8 - Belt 8 Motor | G20: >CBL42 | H20: S84Photo.In | I20: Servo 1 Fwd Photoelectric Switch | J20: 119 | K20: 0M
E21: MS9Vac1 | F21: Motor Starter 9 - Vacuum 1 Pump | G21: RM | H21: Sol3Blt3 | I21: Solenoid Valve 3 Belt 3 | J21: 120 | K21: 0M
E22: MS10Vac2 | F22: Motor Starter 10 - Vacuum 2 Pump | G22: 15M | H22: Sol4Blt4 | I22: Solenoid Valve 4 Belt 4 | J22: 121 | K22: 0M
E23: MS11Vac3 | F23: Motor Starter 11 - Vacuum 3 Pump | H23: Sol21DT2 | I23: Solenoid Valve 21 Detension 2 | J23: 122 | K23: 0M
B24: ClearBatch.In | C24: Clear Batch Button | E24: MS12Vac4 | F24: Motor Starter 12 - Vacuum 4 Pump | H24: S3Photo.In | I24: CS1 Process Photoelectric Switch | J24: 123 | K24: 0M
E25: MS13Water1 | F25: Motor Starter 13 - Water Tank 1 Pump | J25: 124
E26: MS14Water2 | F26: Motor Starter 14 - Water Tank 2 Pump | J26: 125
J27: 126
J28: 127
J29: 128
J30: 129
J31: 130
J32: 131
G33: X67 Field I/O | H33: Servo1POT | I33: Servo 1 Positive Over Travel Limit Switch | J33: 132 | K33: 10M | M33: ENTRY | N33: EXIT
G34: ST12 | H34: Servo1NOT | I34: Servo 1 Negative Over Travel Limit Switch | J34: 133 | K34: 5M | M34: 0M | N34: 0M | O34: S100/S120
G35: >CBL23 | H35: S80Origin.In | I35: Servo 1 Origin Photoelectric Switch | J35: 134 | K35: 10M | M35: 0M | N35: 0M | O35: S101/S121
G36: >CBL43 | H36: S101Reed.In | I36: Flip Up Arm 1/1 Up Reed Switch | J36: 135 | K36: 0M | M36: 0M | N36: 0M | O36: S102/S122
G37: RI | H37: S104Reed.In | I37: Flip Up Arm 2/1 Down Reed Switch | J37: 136 | K37: 3M | M37: 0M | N37: 0M | O37: S103/S123
G38: 15M | H38: S105Reed.In | I38: Flip Up Arm 2/1 Up Reed Switch | J38: 137 | K38: 3M | M38: 0M | N38: 3M | O38: S104/S124
H39: S106Reed.In | I39: Flip Up Arm 2/2 Down Reed Switch | J39: 138 | K39: 0M | M39: 0M | N39: 3M | O39: S105/S125
H40: S107Reed.In | I40: Flip Up Arm 2/2 Up Reed Switch | J40: 139 | K40: 0M | M40: 3M | N40: 0M | O40: S106/S126
...

Sheet Plug
A1: PIN NO. | B1: PLUG 1 | C1: PLUG 2 | D1: PLUG 3 | E1: PLUG 4 | F1: PLUG31 | G1: PLUG32 | H1: PLUG 5 | I1: PLUG 6 | J1: PIN NO. | K1: PLUG33 | L1: PLUG34 | M1: PLUG 7 | N1: PLUG 8 | O1: PLUG 9 | P1: PLUG 39 | Q1: PLUG 10 | R1: PLUG 11 | S1: PLUG 12 | T1: PIN NO. | U1: PLUG 13 | V1: PLUG 14 | W1: PLUG 15 | X1: PLUG 16 | Y1: PLUG 17 | Z1: PLUG 18 | AA1: PIN NO. | AB1: PLUG 19 | AC1: PLUG 20 | AD1: PLUG 21 | AE1: PLUG 22 | AF1: PLUG 23 | AG1: PLUG 24 | AH1: PIN NO. | AI1: PLUG 25 | AJ1: PLUG 26 | AK1: PLUG 27 | AL1: PLUG28 | AN1: PIN NO.
B2: BELTS1 | C2: BELTS2 | D2: BELTS3 | E2: BELTS4 | F2: ED1 | G2: ED2 | H2: VACUUM1 | I2: VACUUM2 | K2: EXTRACT1 | L2: EXTRACT2 | M2: WATER | N2: REMOTE | O2: EMO | P2: EMO | Q2: LASER | R2: CL1 | S2: CS1 | U2: CV1 | V2: CC1 | W2: CC2 | X2: CS2 | Y2: CV2 | Z2: CC3 | AB2: CC4 | AC2: CB1 | AD2: CB2 | AE2: CRB | AF2: CRE | AG2: CLB | AI2: CR1
A3: 1 | B3: 120 | C3: 126 | D3: 132 | E3: 138 | F3: 144 | G3: 150 | H3: 157 | I3: 163 | J3: 1 | K3: 180 | L3: 186 | M3: 170 | N3: 20 | O3: ES2 | P3: ES42 | Q3: 115 | R3: 501 | S3: 505 | T3: 1 | U3: 509 | V3: 513 | W3: 517 | X3: 521 | Y3: 525 | Z3: 529 | AA3: 1 | AB3: 533 | AC3: 537 | AD3: 541 | AE3: 545 | AF3: 549 | AG3: 553 | AH3: 1 | AI3: 557 | AJ3: 561 | AK3: 565 | AL3: 569 | AM3: 596 | AN3: 1
A4: 2 | B4: 121 | C4: 127 | D4: 133 | E4: 139 | F4: 145 | G4: 151 | H4: 158 | I4: 164 | J4: 2 | K4: 181 | L4: 187 | M4: 171N | N4: 21 | O4: ES22 | P4: ES62 | Q4: N | R4: 502 | S4: 506 | T4: 2 | U4: 510 | V4: 514 | W4: 518 | X4: 522 | Y4: 526 | Z4: 530 | AA4: 2 | AB4: 534 | AC4: 538 | AD4: 542 | AE4: 546 | AF4: 550 | AG4: 554 | AH4: 2 | AI4: 558 | AJ4: 562 | AK4: 566 | AL4: 570 | AM4: 597 | AN4: 2
A5: 3 | B5: 122 | C5: 128 | D5: 134 | E5: 140 | F5: 146 | G5: 152 | H5: 159 | I5: 165 | J5: 3 | K5: 182 | L5: 188 | M5: 173 | N5: 22 | O5: ES6 | P5: ES46 | Q5: PE | R5: 503 | S5: 507 | T5: 3 | U5: 511 | V5: 515 | W5: 519 | X5: 523 | Y5: 527 | Z5: 531 | AA5: 3 | AB5: 535 | AC5: 539 | AD5: 543 | AE5: 547 | AF5: 551 | AG5: 555 | AH5: 3 | AI5: 559 | AJ5: 563 | AK5: 567 | AL5: 571 | AM5: 598 | AN5: 3
A6: 4 | B6: PE | C6: PE | D6: PE | E6: PE | F6: PE | G6: PE | H6: PE | I6: PE | J6: 4 | K6: PE | L6: PE | M6: 174N | N6: 23 | O6: ES26 | P6: ES66 | Q6: 112 | R6: PE | S6: PE | T6: 4 | U6: PE | V6: PE | W6: PE | X6: PE | Y6: PE | Z6: PE | AA6: 4 | AB6: PE | AC6: PE | AD6: PE | AE6: PE | AF6: PE | AG6: PE | AH6: 4 | AI6: PE | AJ6: PE | AK6: PE | AL6: PE | AM6: PE | AN6: 4
A7: 5 | B7: 123 | C7: 129 | D7: 135 | E7: 141 | F7: 147 | G7: 153 | H7: 160 | I7: 166 | J7: 5 | K7: 183 | L7: 189 | M7: 114 | N7: SHLD | O7: ES6 | P7: ES46 | Q7: N | R7: SHLD | S7: SHLD | T7: 5 | U7: SHLD | V7: SHLD | W7: SHLD | X7: SHLD | Y7: SHLD | Z7: SHLD | AA7: 5 | AB7: SHLD | AC7: SHLD | AD7: SHLD | AE7: SHLD | AF7: SHLD | AG7: SHLD | AH7: 5 | AI7: SHLD | AJ7: SHLD | AK7: SHLD | AL7: SHLD | AM7: SHLD | AN7: 5
A8: 6 | B8: 124 | C8: 130 | D8: 136 | E8: 142 | F8: 148 | G8: 154 | H8: 161 | I8: 167 | J8: 6 | K8: 184 | L8: 190 | M8: N | O8: ES26 | P8: ES66 | Q8: PE | T8: 6 | AA8: 6 | AH8: 6 | AN8: 6
A9: 7 | B9: 125 | C9: 131 | D9: 137 | E9: 143 | F9: 149 | G9: 155 | H9: 162 | I9: 168 | J9: 7 | K9: 185 | L9: 191 | N9: 30 | O9: ES10 | P9: ES50 | T9: 7 | AA9: 7 | AH9: 7 | AN9: 7
A10: 8 | B10: PE | C10: PE | D10: PE | E10: PE | F10: PE | G10: PE | H10: PE | I10: PE | J10: 8 | K10: PE | L10: PE | N10: 30 | O10: ES30 | P10: ES70 | T10: 8 | AA10: 8 | AH10: 8 | AN10: 8
A11: 9 | H11: 182 | I11: 185 | J11: 9 | N11: 31 | O11: ES10 | P11: ES50 | T11: 9 | AA11: 9 | AG11: 574 | AH11: 9 | AK11: 574 | AN11: 9
A12: 10 | H12: 183N | I12: 186N | J12: 10 | N12: 31 | O12: ES30 | P12: ES70 | T12: 10 | AA12: 10 | AG12: N | AH12: 10 | AK12: N | AN12: 10
A13: 11 | J13: 11 | O13: ES14 | P13: ES54 | T13: 11 | AA13: 11 | AH13: 11 | AN13: 11
A14: 12 | J14: 12 | O14: ES34 | P14: ES74 | T14: 12 | AA14: 12 | AH14: 12 | AN14: 12
A15: 13 | J15: 13 | O15: ES14 | P15: ES54 | T15: 13 | AA15: 13 | AH15: 13 | AN15: 13
A16: 14 | J16: 14 | O16: ES34 | P16: ES74 | T16: 14 | AA16: 14 | AH16: 14 | AN16: 14
A17: 15 | J17: 15 | O17: ES20 | P17: ES60 | T17: 15 | AA17: 15 | AH17: 15 | AN17: 15
A18: 16 | J18: 16 | O18: ES40 | P18: ES80 | T18: 16 | AA18: 16 | AH18: 16 | AN18: 16
A19: PIN NO. | B19: =(B1) -> PLUG 1 | C19: =(C1) -> PLUG 2 | D19: =(D1) -> PLUG 3 | E19: =(E1) -> PLUG 4 | F19: =(F1) -> PLUG31 | G19: =(G1) -> PLUG32 | H19: =(H1) -> PLUG 5 | I19: =(I1) -> PLUG 6 | J19: PIN NO. | K19: =(K1) -> PLUG33 | L19: =(L1) -> PLUG34 | M19: =(M1) -> PLUG 7 | N19: =(N1) -> PLUG 8 | O19: =(O1) -> PLUG 9 | P19: =(P1) -> PLUG 39 | Q19: =(Q1) -> PLUG 10 | R19: =(R1) -> PLUG 11 | S19: =(S1) -> PLUG 12 | T19: PIN NO. | U19: =(U1) -> PLUG 13 | V19: =(V1) -> PLUG 14 | W19: =(W1) -> PLUG 15 | X19: =(X1) -> PLUG 16 | Y19: =(Y1) -> PLUG 17 | Z19: =(Z1) -> PLUG 18 | AA19: PIN NO. | AB19: =(AB1) -> PLUG 19 | AC19: =(AC1) -> PLUG 20 | AD19: =(AD1) -> PLUG 21 | AE19: =(AE1) -> PLUG 22 | AF19: =(AF1) -> PLUG 23 | AG19: =(AG1) -> PLUG 24 | AH19: PIN NO. | AI19: =(AI1) -> PLUG 25 | AJ19: =(AJ1) -> PLUG 26 | AK19: =(AK1) -> PLUG 27 | AL19: =(AL1) -> PLUG28 | AM19: =(AM1) -> 0 | AN19: PIN NO.

Sheet AC
A1: Panel AC Current Consumption | T1: Electrical Calculations
T2: E = VOLTS
A3: Three Phase Equipment | T3: P = WATTS
N4: Double Check Values | T4: R = OHMS
A5: Description | B5: Qty | C5: Current (A) | D5: Total Current (A) | K5: kW | L5: Total kW | N5: A from kW | O5: kW from A | T5: I = AMPERES
A6: Belt Motor | B6: 8 | C6: 3.05 | D6: =SUM(B6*C6) -> 24.4 | K6: 1.75 | L6: =K6*B6 -> 14 | N6: =K6/0.57436 -> 3.0468696 | O6: =C6*0.57436 -> 1.751798 | T6: HP = HORSEPOWER
A7: Edge Deletion Motor | B7: 0 | C7: 1.1 | D7: =SUM(B7*C7) -> 0 | K7: 0.44 | L7: =K7*B7 -> 0 | N7: =K7/0.57436 -> 0.76607006 | O7: =C7*0.57436 -> 0.631796 | T7: PF = POWER FACTOR
A8: Vacuum | B8: 4 | C8: 9 | D8: =SUM(B8*C8) -> 36 | K8: 5 | L8: =K8*B8 -> 20 | N8: =K8/0.57436 -> 8.7053416 | O8: =C8*0.57436 -> 5.16924 | T8: kW = KILOWATTS
A9: Recycling Pump | B9: 0 | C9: 2.6 | D9: =SUM(B9*C9) -> 0 | K9: 1.5 | L9: =K9*B9 -> 0 | N9: =K9/0.57436 -> 2.6116025 | O9: =C9*0.57436 -> 1.493336 | T9: kWh = KILOWATT HOUR
A10: Floatation Fans | B10: 0 | C10: 2.6 | D10: =SUM(B10*C10) -> 0 | K10: 1.5 | L10: =K10*B10 -> 0 | N10: =K10/0.57436 -> 2.6116025 | O10: =C10*0.57436 -> 1.493336 | T10: VA = VOLT-AMPERES
A11: Servo Motors | B11: 2 | C11: 3.78 | D11: =SUM(B11*C11) -> 7.56 | K11: 1.94 | L11: =K11*B11 -> 3.88 | N11: =K11/0.57436 -> 3.3776725 | O11: =C11*0.57436 -> 2.1710808 | T11: kVA = KILOVOLT-AMPERES
A12: Dry Dust Extraction First Try | B12: 0 | C12: 7 | D12: =SUM(B12*C12) -> 0 | K12: 4 | L12: =K12*B12 -> 0 | N12: =K12/0.57436 -> 6.9642733 | O12: =C12*0.57436 -> 4.02052 | T12: C = CAPACITANCE
A13: 12A 24V Power Supply | B13: 1 | C13: 2 | D13: =SUM(B13*C13) -> 2 | K13: 1.15 | L13: =K13*B13 -> 1.15 | N13: =K13/0.57436 -> 2.0022286 | O13: =C13*0.57436 -> 1.14872 | T13: DIRECT CURRENT
A14: Standalone Arrisser | B14: 0 | C14: 10 | D14: =SUM(B14*C14) -> 0 | K14: 5.5 | L14: =K14*B14 -> 0 | N14: =K14/0.57436 -> 9.5758758 | O14: =C14*0.57436 -> 5.7436 | T14: AMPS = | U14: WATTS | V14: ÷ VOLTS | W14: (I = P ÷ E)
K15: Total kW of 3 Phase Equipment | T15: =FLOOR((U15/V15),0.01) -> 0.95 | U15: 23 | V15: 24
D16: =SUM(D6:F14) -> 69.96 | L16: =SUM(L6:L14) -> 39.03 | N16: =L16/0.57436 -> 67.953897 | O16: =D16*0.57436 -> 40.182226 | T16: WATTS = | U16: VOLTS | V16: x AMPS | W16: (P = E x I)
T17: =FLOOR((U17*V17),0.1) -> 50 | U17: 5 | V17: 10
A18: Single Phase Equipment | E18: Phases | H18: Phases | T18: VOLTS = | U18: WATTS | V18: ÷ AMPS
C19: Current (A) | D19: Br | E19: Bl | F19: Gr | G19: RED | H19: YELLOW | I19: BLUE | T19: =FLOOR((U19/V19),0.1) -> 5 | U19: 50 | V19: 10
A20: Inverter 2.2kW | B20: 14 | C20: 9.2 | D20: 5 | E20: 5 | F20: 4 | G20: =(C20*D20) -> 46 | H20: =(C20*E20) -> 46 | I20: =(C20*F20) -> 36.8 | K20: 2.2 | L20: =K20*B20 -> 30.8
A21: Evacuation/Recycle Pump | B21: 2 | C21: 2.9 | E21: 1 | F21: 1 | G21: =(C21*D21) -> 0 | H21: =(C21*E21) -> 2.9 | I21: =(C21*F21) -> 2.9 | K21: 0.67 | L21: =K21*B21 -> 1.34 | T21: AC SINGLE PHASE ~1Ø
A22: Recycle Pump Large | B22: 0 | C22: 5.6 | G22: =(C22*D22) -> 0 | H22: =(C22*E22) -> 0 | I22: =(C22*F22) -> 0 | T22: Known Values
A23: Mains Contactor | B23: 1 | C23: 1.9 | F23: 1 | G23: =(C23*D23) -> 0 | H23: =(C23*E23) -> 0 | I23: =(C23*F23) -> 1.9 | K23: 0.44 | L23: =K23*B23 -> 0.44 | T23: Amps | U23: 0.2 | V23: Volts | W23: 240 | X23: kW | Y23: 2.2
A24: Laser | B24: 1 | C24: 10 | F24: 1 | G24: =(C24*D24) -> 0 | H24: =(C24*E24) -> 0 | I24: =(C24*F24) -> 10 | K24: 1 | L24: =K24*B24 -> 1 | U24: (Input any two values above)
A25: Laser HMI | B25: 1 | C25: 6 | D25: 1 | G25: =(C25*D25) -> 6 | H25: =(C25*E25) -> 0 | I25: =(C25*F25) -> 0
A26: Auxiliaries (Laptop and Lamp) | B26: 0 | C26: 2.5 | G26: =(C26*D26) -> 0 | H26: =(C26*E26) -> 0 | I26: =(C26*F26) -> 0 | K26: 0.6 | L26: =K26*B26 -> 0 | T26: AMPS = | U26: WATTS | V26: ÷ (VOLTS | W26: x PF) | X26: (I = P ÷ (E x PF))
A27: Auxiliaries (Fans) | B27: 0 | C27: 0.5 | G27: =(C27*D27) -> 0 | H27: =(C27*E27) -> 0 | I27: =(C27*F27) -> 0 | K27: 0.12 | L27: =K27*B27 -> 0 | T27: =FLOOR(((U27)/(V27*W27)),0.01) -> 9.16 | U27: =Y23*1000 -> 2200 | V27: =W23 -> 240 | W27: 1
A28: Shunt Trip | B28: 1 | C28: 0.02 | F28: 1 | G28: =(C28*D28) -> 0 | H28: =(C28*E28) -> 0 | I28: =(C28*F28) -> 0.02 | K28: 0.12 | L28: =K28*B28 -> 0.12 | T28: WATTS = | U28: VOLTS | V28: x AMPS | W28: x PF | X28: (P = E x I x PF)
A29: Air Conditioning | B29: 1 | C29: 4.5 | E29: 1 | G29: =(C29*D29) -> 0 | H29: =(C29*E29) -> 4.5 | I29: =(C29*F29) -> 0 | K29: 1.1 | L29: =K29*B29 -> 1.1 | N29: 1 Phase KVA | O29: =(D34*240)/1000 -> 12.876 | P29: KVA | T29: =FLOOR((U29*V29*W29),0.01) -> 48 | U29: =W23 -> 240 | V29: =U23 -> 0.2 | W29: =T35 -> 1
A30: Filstar | B30: 1 | C30: 0.25 | E30: 1 | G30: =(C30*D30) -> 0 | H30: =(C30*E30) -> 0.25 | I30: =(C30*F30) -> 0 | N30: = | T30: VOLTS = | U30: WATTS | V30: ÷ AMPS | W30: (E = P ÷ I)
G31: =(C31*D31) -> 0 | H31: =(C31*E31) -> 0 | I31: =(C31*F31) -> 0 | N31: 3 Phase KVA | O31: =O29/0.55 -> 23.410909 | P31: KVA | T31: =FLOOR((U31/V31),0.01) -> 11000 | U31: =Y23*1000 -> 2200 | V31: =U23 -> 0.2
G32: =(C32*D32) -> 0 | H32: =(C32*E32) -> 0 | I32: =(C32*F32) -> 0 | N32: Total 3 Phase kW for 1 Phase Equipment | T32: VOLT-AMPS | U32: = VOLTS | V32: x AMPS | W32: (VA = E x I)
K33: Total kW of 1 Phase Equipment | T33: =FLOOR((U33*V33),0.01) -> 48 | U33: =W23 -> 240 | V33: =U23 -> 0.2
D34: =MAX(G34:I34) -> 53.65 | G34: =SUM(G20:G32) -> 52 | H34: =SUM(H20:H32) -> 53.65 | I34: =SUM(I20:I32) -> 51.62 | L34: =SUM(L20:L32) -> 34.8 | O34: =O31/0.8 -> 29.263636 | P34: kW | T34: PF = | U34: WATTS | V34: ÷ (VOLTS | W34: x AMPS) | X34: (PF = W ÷ (E x I)
E35: Input Highest of 3 values | T35: 1 | U35: =Y23*1000 -> 2200 | V35: =W23 -> 240 | W35: =U23 -> 0.2
C36: Total Amps | D36: =D16+D34&"A" -> 123.61A | N36: (Calculated from 1 Phase Amps)
K37: 100 | L37: =K37*0.57436 -> 57.436 | O37: =O34/0.57436 -> 50.94999 | T37: AC THREE PHASE ~3Ø
T38: Known Values
L39: =L34+L16&"kW" -> 73.83kW | M39: Figure for customer | O39: =(L34+L16)/0.57436 -> 128.54307 | T39: Amps | U39: 3.82 | V39: Volts | W39: 400 | X39: kW | Y39: 4
D40: FULL LOAD KW = | E40: =CEILING(O34+L16,1) -> 69 | F40: KW | H40: =(SQRT(3))*400 -> 692.82032 | U40: (Input any two values above)
...

Sheet Tracking
A1: Tracking00 | B1: X | C1: LOADING CONVEYOR | J1: 4
C2: Start Condition | D2: Edge | E2: End Condition | F2: Edge | H2: Timeout # | I2: Timeout Type | J2: INV | K2: INV | L2: INV
A3: Track001 | C3: S45Foot.In | D3: P | E3: S31Reed.In | F3: P | H3: 0 | I3: Pallet
A4: Track002 | C4: S31Reed.In | D4: P | E4: S1Photo.Int | F4: P | H4: 1 | I4: Distance | J4: CL1
A5: Track003 | C5: S1Photo.Int | D5: P | E5: S2Photo.Int | F5: P | H5: 2 | I5: Distance | J5: CL1
A6: Track004 | C6: S2Photo.Int | D6: P | E6: Ax1.SeekFin | F6: P | I6: Motion
A7: Track005 | C7: Ax1.SeekFin | D7: P | E7: NOT Tracking00.Blocked | F7: - | I7: Block | M7: Use Track011 as Block if laser selected
A8: Tracking90 | B8: X | C8: LOADING RUN ON | J8: R
C9: Start Condition | D9: Edge | E9: End Condition | F9: Edge | H9: Timeout # | I9: Timeout Type | J9: INV | K9: INV | L9: INV
A10: Track901 | C10: NOT Tracking00.Blocked | D10: - | E10: S2Photo.Int | F10: N | I10: Distance | J10: CL1
A12: Tracking01 | B12: X | C12: LASER | J12: 4
C13: Start Condition | D13: Edge | E13: End Condition | F13: Edge | H13: Timeout # | I13: Timeout Type | J13: INV | K13: INV | L13: INV
A14: Track011 | C14: S2Photo.Int | D14: P | E14: Track011.DelayTON.Q | F14: - | G14: Delay for Laser Positioning | I14: Delay
A15: Track012 | C15: Track011.DelayTON.Q | D15: - | E15: LaserBusy.In | F15: N | I15: Laser
A16: Track013 | C16: LaserBusy.In | D16: N | E16: NOT Tracking01.Blocked | F16: - | I16: Block | M16: Use Track004 as Block if laser selected
A18: Tracking10 | B18: X | C18: SEAMING CONVEYOR 1 | J18: 5
C19: Start Condition | D19: Edge | E19: End Condition | F19: Edge | H19: Timeout # | I19: Timeout Type | J19: INV | K19: INV | L19: INV
A20: Track101 | C20: NOT Tracking00.Blocked | D20: - | E20: S4Photo.Int | F20: P | H20: 3 | I20: Distance | J20: CS1 | K20: CC1 | N20: Changed V3.0
A21: Track102 | C21: S3Photo.Int | D21: P | E21: S3Photo.Int | F21: N | H21: 4 | I21: Distance | J21: CS1 | K21: CC1 | N21: Removed V3.0
A22: Track103 | C22: S3Photo.Int | D22: N | E22: Belts1.Done | F22: P | I22: Seaming | J22: CS1 | K22: CC1 | N22: Removed V3.0
A23: Track104 | C23: S4Photo.Int | D23: P | E23: S4Photo.Int | F23: N | H23: 5 | I23: Distance | J23: CS1 | K23: CC1 | N23: Changed V3.0
A24: Track105 | C24: 54Photo.Int | D24: N | E24: Track105.DelayTON.Q | F24: P | G24: Delay for CC1 Slow | I24: Delay | J24: CS1 | K24: CC1
A25: Track106 | C25: Track105.DelayTON.Q | D25: P | E25: S50Reed.In | F25: P | H25: 6 | I25: Gate
A26: Track107 | C26: S50Reed.In | D26: P | E26: Track107.DelayTON.Q | F26: P | G26: Delay for CC1 Rev | I26: Delay | J26: CC1(R)
A27: Track108 | C27: Track107.DelayTON.Q | D27: P | E27: NOT Tracking10.Blocked | F27: - | I27: Block
A28: Tracking91 | B28: X | C28: CORNER CONVEYOR 1 RUN ON | J28: R
C29: Start Condition | D29: Edge | E29: End Condition | F29: Edge | H29: Timeout # | I29: Timeout Type | J29: INV | K29: INV | L29: INV
A30: Track911 | C30: NOT Tracking11.Blocked | D30: - | E30: NOT S9Photo.Int | F30: - | I30: Distance | J30: CC2
A31: Track912 | C31: NOT S9Photo.Int | D31: - | E31: S5Photo.Int | F31: N | I31: Distance | J31: CC2
A32: Track913 | C32: S5Photo.Int | D32: N | E32: S7Photo.Int | F32: N | I32: Delay | J32: CC2
A34: Tracking11 | B34: X | C34: CORNER CONVEYOR 1 | J34: 6
C35: Start Condition | D35: Edge | E35: End Condition | F35: Edge | H35: Timeout # | I35: Timeout Type | J35: INV | K35: INV | L35: INV
A36: Track111 | C36: NOT Tracking10.Blocked | D36: P | E36: S32Reed.In | F36: P | H36: 7 | I36: Pallet
A37: Track112 | C37: S32Reed.In | D37: P | E37: S6Photo.Int | F37: P | H37: 8 | I37: Distance | J37: CC2
A38: Track113 | C38: S6Photo.Int | D38: P | E38: S7Photo.Int | F38: P | H38: 9 | I38: Distance | J38: CC2
A39: Track114 | C39: S7Photo.Int | D39: P | E39: Ax2.SeekFin | F39: P | I39: Motion
A40: Track115 | C40: Ax2.SeekFin | D40: P | E40: NOT Tracking11.Blocked | F40: - | I40: Block
C41: Start Condition | D41: Edge | E41: End Condition | F41: Edge | H41: Timeout # | I41: Timeout Type | J41: INV | K41: INV | L41: INV
A42: Track941 | C42: NOT Tracking11.Blocked | D42: - | E42: S7Photo.Int | F42: N | I42: Distance | J42: CC2
A44: Tracking20 | B44: X | C44: SEAMING CONVEYOR 2 | J44: 0
...

Sheet X2
A1: X2
A2: 4L1 | B2: 4L2 | C2: 4L3 | D2: Pole 4
A3: 1 | B3: 15 | C3: 29 | D3: 43
A4: 2 | B4: 16 | C4: 30 | D4: 44
A5: 3 | B5: 17 | C5: 31 | D5: 45
A6: 4 | B6: 18 | C6: 32 | D6: 46
A7: 5 | B7: 19 | C7: 33 | D7: 47
A8: 6 | B8: 20 | C8: 34 | D8: 48
A9: 7 | B9: 21 | C9: 35 | D9: 49
A10: 8 | B10: 22 | C10: 36 | D10: 50
A11: 9 | B11: 23 | C11: 37 | D11: 51
A12: 10 | B12: 24 | C12: 38 | D12: 52
A13: 11 | B13: 25 | C13: 39 | D13: 53
A14: 12 | B14: 26 | C14: 40 | D14: 54
... A16: 14 | B16: 28 | C16: 42 | D16: 56

Sheet Program Checklist
A1: HARDWARE CONFIGURATION | C1: VISUALISATION
A2: Enable/Disable Inverter | C2: COMMON LAYERS:
A3: X2X list | C3: WASHHEIGHT
A4: X2X supervised off | C4: P10_MENU
A5: X2X DIO | C5: P11_MIMIC | D5: Track584 Block | F5: Track681 | G5: Track682 | H5: Track683 | I5: Tracking68.Index | K5: CRE Speed on Washer Tab
A6: X2X Mapping | C6: P12_OPTIONS | D6: Batching Modes Drop down
A7: InvPars Enable/Disable Inverters | C7: P13_SETTINGS | D7: Analog scaling | F7: Delay for resetting multiple, CF2Slow1
A8: SOFTWARE CONFIGURATION | C8: P14_DRIVES
A9: IO Program | C9: P15_SERVOS | D9: Analog scaling
A10: SensorInput Program | C10: P16_RIO
A11: Timeouts Program | C11: P17_ALARM
A12: LineConfig Program Commenting | C12: P18_WARNING
A13: Control.Empty Conditions | C13: P19_EVENT
A14: Track13 Conditions | C14: P20_ASHTON_TECH
A15: Track33 Conditions | C15: P21_SDM
A16: ResetBits Program Commenting
A17: ConRobot Program Commenting
A18: ConFeed Program Commenting
A19: ConLoad Program Commenting
A20: ConSeam1 Program Commenting
A21: Seaming1 Program Commenting
A22: ConCorner Program Commenting
A23: ConSeam2 Program Commenting
A24: Seaming2 Program Commenting
A25: ConRunout Program Commenting
A26: ConRow Program Commenting
A27: ConRows Program Commenting
... A74: RUMTIME COMPLETION CONTROLS FOR ACCEL/DECEL INVERTER PARAMETERS

Sheet Motors
C2: CL1 | D2: CS1 | E2: CV1 | F2: CC1 | G2: CC2 | H2: CS2 | I2: CV2 | J2: CC3 | K2: CC4 | L2: CB1 | M2: CB2 | N2: CRB | O2: CRE | P2: CLB
B3: Parameter | C3: INV1 | D3: INV2 | E3: INV3 | F3: INV4 | G3: INV5 | H3: INV6 | I3: INV7 | J3: INV8 | K3: INV9 | L3: INV10 | M3: INV11 | N3: INV12 | O3: INV13 | P3: INV14
C4: XM00151 | D4: XM00157 | E4: XM00157 | F4: XM00151 | G4: XM00152 | H4: XM00157 | I4: XM00157 | J4: XM00152 | K4: XM00151 | L4: XM00151 | M4: XM00151 | N4: XM00151 | O4: XM00152 | P4: XM00155
A5: KW | B5: NPR | C5: 220 | D5: 220 | E5: 220 | F5: 220 | G5: 220 | H5: 220 | I5: 220 | J5: 220 | K5: 220 | L5: 220 | M5: 220 | N5: 220 | O5: 220 | P5: 220
A6: Cos | B6: COS | C6: 76 | D6: 85 | E6: 85 | F6: 76 | G6: 85 | H6: 85 | I6: 85 | J6: 85 | K6: 76 | L6: 76 | M6: 76 | N6: 76 | O6: 85 | P6: 85
A7: Rated Motor Voltage | B7: UNS | C7: 230 | D7: 230 | E7: 230 | F7: 230 | G7: 230 | H7: 230 | I7: 230 | J7: 230 | K7: 230 | L7: 230 | M7: 230 | N7: 230 | O7: 230 | P7: 230
A8: Rated Motor Current | B8: NCR | C8: 86 | D8: 80 | E8: 80 | F8: 86 | G8: 80 | H8: 80 | I8: 80 | J8: 80 | K8: 86 | L8: 86 | M8: 86 | N8: 86 | O8: 80 | P8: 80
A9: Rated Motor Frequency | B9: FRS | C9: 500 | D9: 500 | E9: 500 | F9: 500 | G9: 500 | H9: 500 | I9: 500 | J9: 500 | K9: 500 | L9: 500 | M9: 500 | N9: 500 | O9: 500 | P9: 500
A10: Rated Motor Speed | B10: NSP | C10: 1420 | D10: 2772 | E10: 2772 | F10: 1420 | G10: 2870 | H10: 2772 | I10: 2772 | J10: 2870 | K10: 1420 | L10: 1420 | M10: 1420 | N10: 1420 | O10: 2870 | P10: 2870
A12: Roller Conveyor | C12: XM00152
A13: Belt Conveyor | C13: XM00151
A14: Roller Conveyor w/Blower | C14: XM00155
A15: SM Pro Seamer Conveyor | C15: XM00157
C19: 1 | D19: CL1 | E19: CL1 | G19: CC5 > | H19: CB2 | J19: .Input | K19: .Module | L19: .Output
C20: 2 | D20: CL2 | E20: CL2 | G20: CB1 > | H20: CC5
C21: 3 | D21: CS1 | E21: CB1 | G21: CS1 > | H21: CB1
C22: 4 | D22: CC1 | E22: CS1 | G22: CC1 > | H22: CS1
C23: 5 | D23: CC2 | E23: CC1 | G23: CC2 > | H23: CC1
C24: 6 | D24: CS2 | E24: CC2 | G24: CS2 > | H24: CC2
C25: 7 | D25: CC3 | E25: CS2 | G25: CC3 > | H25: CS2
C26: 8 | D26: CC4 | E26: CC3 | G26: CC4 > | H26: CC3
C27: 9 | D27: CS3 | E27: CC4 | G27: CS3 > | H27: CC4
C28: 10 | D28: CC5 | E28: CB2 | G28: CC6 > | H28: CS3
C29: 11 | D29: CC6 | E29: CS3 | G29: CS4 > | H29: CC6
C30: 12 | D30: CB1 | E30: CC5 | G30: CR1 > | H30: CS4
C31: 13 | D31: CS4 | E31: CC6
C32: 14 | D32: CR1 | E32: CS4
C33: 15 | E33: CR1

Sheet Cycle Time
A1: Cycle Times Calculation
C2: Length | D2: Width | E2: Washer Speed
A3: Loading Conveyor | C3: 1100 | D3: 1000 | E3: 12
C4: Dist in mm | D4: Speed | E4: Time | G4: Section 1 End loading to Seamer 1
A5: Track102 | B5: Track from CL1.o.Fwd[0] (P) to S1Photo.Int (P) | C5: 3310 | D5: 45 | E5: =(C5/(D5/0.06)) -> 4.4133333 | G5: Assume 500mm of glass placed on conveyor
A6: Track107 | B6: Track from S1Photo.Int (P) to S31Reed.In (P) | E6: 0.5 | G6: Pallet Lift
A7: Track108 | B7: Track from S31Reed.In (P) to CL2Slow.Q (P) | E7: 1 | G7: Squaring Delay
A8: Track109 | B8: Track from CL2Slow.Q (P) to S30Reed.In (P) | E8: 0.5 | G8: Pallet Lower
A9: Track10A | B9: Track from S30Reed.In (P) to S3Photo.Int (P) | C9: 200 | D9: 10 | E9: =(C9/(D9/0.06)) -> 1.2 | G9: To Seek and Find position
A10: Track09 | B10: S3Photo.Int (P) to Tracking0.Fin (P) | E10: 3 | G10: Seek and Find
A11: Track10 | B11: Tracking0.Fin (P) to NOT Tracking1.Blocked (-) | E11: 0 | G11: Waiting for following conveyors to clear
E13: =SUM(E5:E11) -> 10.613333
A15: Time to Clear | C15: Dist in mm | D15: Speed | E15: Time
A16: Track11 | B16: NOT Tracking1.Blocked (-) to S3Photo.Int (N) | C16: =C3 -> 1100 | D16: 35 | E16: =(C16/(D16/0.06)) -> 1.8857143 | G16: Back edge of glass to clear C1
D18: Section 1 Cycle time | E18: =E16+E13 -> 12.499048 | G18: Time before next loading
A21: Seamer 1 | C21: Dist in mm | D21: Speed | E21: Time | G21: Section 2 Seamer 1 to End of C3
A22: Track11 | B22: NOT Tracking1.Blocked (-) to S3Photo.Int (N) | C22: =C3 -> 1100 | D22: 35 | E22: =(C22/(D22/0.06)) -> 1.8857143 | G22: Back edge of glass to clear C1
A23: Track12 | B23: S3Photo.Int (N) to S4Photo.Int (N) | C23: 200 | D23: 35 | E23: =(C23/(D23/0.06)) -> 0.34285714 | G23: Back edge of glass to clear Process sensor
A24: Track413 | B24: Track from S4Photo.Int (N) to Belts1.Done (P) | C24: 800 | D24: 35 | E24: =(C24/(D24/0.06)) -> 1.3714286 | G24: Back edge of glass to clear grinding belts
A25: Track414 | B25: Track from Belts1.Done (P) to S25Photo.Int (P) | C25: 310 | D25: 45 | E25: =(C25/(D25/0.06)) -> 0.41333333 | G25: Leading edge to end of C3
A26: Track415 | B26: Track from S25Photo.Int (P) to NOT Tracking501.Blocked (-) | E26: 0 | G26: Waiting for following conveyors to clear
E28: =SUM(E22:E26) -> 4.0133333
A30: Time to Clear | C30: Dist in mm | D30: Speed | E30: Time
A31: Track516 | B31: Track from NOT Tracking501.Blocked (-) to S6Photo.Int (P) | C31: 3760 | D31: 45 | E31: =(C31/(D31/0.06)) -> 5.0133333 | G31: To slow down sensor C4.
D33: Section 2 Cycle time | E33: =SUM(E31+E28) -> 9.0266667 | G33: Time before following section can restart
C35: Dist in mm | D35: Speed | E35: Time | G35: Section 3 End of C3 to Seamer 2
A36: Track516 | B36: Track from NOT Tracking501.Blocked (-) to S6Photo.Int (P) | C36: 3760 | D36: 45 | E36: =(C36/(D36/0.06)) -> 5.0133333 | G36: To slow down sensor C4.
A37: Track517 | B37: Track from S6Photo.Int (P) to CC1Slow.Q (P) | E37: 1.2 | G37: Squaring to Datum
A38: Track519 | B38: Track from CC1Slow.Q (P) to S33Reed.In (P) | E38: 0.5 | G38: Pallet Lift
A39: Track26 | B39: Track from S33Reed.In (P) to S8Photo.Int (P) | C39: 150 | D39: 35 | E39: =(C39/(D39/0.06)) -> 0.25714286 | G39: To slow down sensor
A40: Track27 | B40: Track from S8Photo.Int (P) to S9Photo.Int (P) | C40: 150 | D40: 10 | E40: =(C40/(D40/0.06)) -> 0.9 | G40: To Seek and Find position
A41: Track29 | B41: S9Photo.Int (P) to Ax2.SeekFin (P) | E41: 3 | G41: Seek and Find
A42: Track30 | B42: Ax2.SeekFin (P) to NOT Tracking3.Blocked (-) | E42: 0 | G42: Waiting for following conveyors to clear
E44: =SUM(E36:E42) -> 10.870476
A46: Time to Clear | C46: Dist in mm | D46: Speed | E46: Time
A47: Track31 | B47: NOT Tracking3.Blocked (-) to S9Photo.Int (N) | C47: =D3 -> 1000 | D47: 35 | E47: =(C47/(D47/0.06)) -> 1.7142857 | G47: Back edge of glass to clear C4
B48: Pallet Down | E48: 0.5 | G48: Pallet Lower
D50: Section 3 Cycle time | E50: =SUM(E44:E48) -> 13.084762 | F50: *1
A53: Seamer 2 | C53: Dist in mm | D53: Speed | E53: Time | G53: Row Building
A54: Track31 | B54: NOT Tracking3.Blocked (-) to S9Photo.Int (N) | C54: =D3 -> 1000 | D54: 35 | E54: =(C54/(D54/0.06)) -> 1.7142857 | G54: Back edge of glass to clear C4
...

Sheet Visualisation
A1: Checklist to create Service Visualisation.
A2: 1 | B2: Delete SRVXGA Visualisation.
A3: 2 | B3: Add object, new visualisation (Empty).
A4: 3 | B4: Import 'HMI' visualisation, overwrite where necessary, into new visualisation 'SRVXGA'.
A5: 4 | B5: Delete 'Resources' page.
A6: 5 | B6: Amend all page numbering
A7: 6 | B7: Add Page controls | D7: Default>Page | F7: P00_INITIALIZE
D8: Page>ChangeDatapoint | F8: PLC.VisControl.ServiceVis.Page.New
D9: Page>CurrentDatapoint | F9: PLC.VisControl.ServiceVis.Page.Current
A10: 7 | B10: ETH1 Configuration | D10: VNC Server 2> VC object name | F10: SRVXGA
A11: 8 | B11: Add VNC passwords to ETH1 Configuration
A12: 9 | B12: Refactor Vis to ServiceVis
A13: 10 | B13: Refactor Level to ServiceLevel
A14: 11 | B14: Refactor ServiceVis.EMO to Vis.EMO
A15: 12 | B15: Change TouchPad in Color > Numeric > Input Styleclass to Numpad
A16: 13 | B16: Any changes made to HMIControl programmes, must be made to ServiceControl programs
A17: 14 | B17: If 14 true, change all Vis. To ServiceVis. And Level. To ServiceLevel.
C24: Mimic Help | D24: Runtime | E24: Type | F24: Layer
C25: Position 1 | D25: Vis.P11.Status[0]
C26: Tracking20.Busy | D26: Vis.P11.Status1[0] | E26: RESET | F26: Help1_1 | H26: SEAMER 2
C27: Track208.Active | D27: Vis.P11.Layers.Layer1 | E27: BLOCK | F27: Help1_1Block
C28: Position 2 | D28: Vis.P11.Status[1]
C29: Tracking30.Busy | D29: Vis.P11.Status1[1] | E29: RESET | F29: Help2_1 | H29: BUFFER 1
C30: Track302.Active | D30: Vis.P11.Layers.Layer2 | E30: BLOCK | F30: Help2_1Block
C31: Position 3 | D31: Vis.P11.Status[2]
C32: Tracking40.Busy | D32: Vis.P11.Status1[2] | E32: RESET | F32: Help3_1 | H32: BUFFER 2
C33: Track402.Active | D33: Vis.P11.Layers.Layer3 | E33: BLOCK | F33: Help3_1Block
C34: Tracking41.Busy | D34: Vis.P11.Status1[3] | E34: RESET | F34: Help3_2
C35: Position 4 | D35: Vis.P11.Status[3]
C36: Tracking50.Busy | D36: Vis.P11.Status1[4] | E36: RESET | F36: Help4_1 | H36: ROW BUILDING
C37: Tracking80.Busy | D37: Vis.P11.Status1[5] | E37: RESET | F37: Help4_2
C38: Tracking51.Busy | D38: Vis.P11.Status1[13] | E38: RESET | F38: Help4_3
C39: Track513.Active | D39: Vis.P11.Layers.Layer11 | E39: BLOCK | F39: Help4_3Block
C40: Position 5 | D40: Vis.P11.Status[4]
C41: Tracking60.Busy | D41: Vis.P11.Status1[6] | E41: RESET | F41: Help5_1 | H41: LOAD BUILDING
C42: Track603.Active | D42: Vis.P11.Layers.Layer4 | E42: BLOCK | F42: Help5_1Block
C43: Tracking70.Busy | D43: Vis.P11.Status1[7] | E43: RESET | F43: Help5_2
C44: Tracking81.Busy | D44: Vis.P11.Status1[8] | E44: RESET | F44: Help5_3
C45: Track812.Active | D45: Vis.P11.Layers.Layer5 | E45: BLOCK | F45: Help5_3Block
C46: Tracking82.Busy | D46: Vis.P11.Status1[9] | E46: RESET | F46: Help5_4
...

Sheet Next Size
A2: LoadDisplay.Count = 1
A3: Width[0] = 0.0
A4: Row 1 | B4: Row 2
A5: 1 | M5: 45 POSSIBLE COMBINATIONS WITH UP TO 4 PIECES
A6: Width[0] > 0.0 | M6: 93 POSSIBLE COMBINATIONS WITH UP TO 5 PIECES
A7: Row 1 | B7: Row 2
A8: 0 | B8: 1
A9: 1
A11: LoadDisplay.Count = 2
A12: Width[0] = 0.0
A13: Row 1 | C13: Row 2
A14: 1 | B14: 0 | C14: 1
A15: 1 | B15: 1
A16: Width[0] > 0.0
A17: Row 1 | C17: Row 2 | E17: Row 3
A18: 0 | B18: 0 | C18: 1 | D18: 0 | E18: 1
A19: 0 | B19: 0 | C19: 1 | D19: 1
A20: 1 | B20: 0 | C20: 1
A21: 1 | B21: 1
A23: LoadDisplay.Count = 3
A24: Width[0] = 0.0
A25: Row 1 | D25: Row 2 | G25: Row 3
A26: 1 | B26: 0 | C26: 0 | D26: 1 | E26: 0 | F26: 0 | G26: 1 | O26: =SUM(A26:N26) -> 3 | P26: D
A27: 1 | B27: 0 | C27: 0 | D27: 1 | E27: 1 | O27: =SUM(A27:N27) -> 3 | P27: C
A28: 1 | B28: 1 | C28: 0 | D28: 1 | O28: =SUM(A28:N28) -> 3 | P28: B
A29: 1 | B29: 1 | C29: 1 | P29: A
A30: Width[0] > 0.0
A31: Row 1 | D31: Row 2 | G31: Row 3 | J31: Row 4
A32: 0 | B32: 0 | C32: 0 | D32: 1 | E32: 0 | F32: 0 | G32: 1 | H32: 0 | I32: 0 | J32: 1 | O32: =SUM(A32:N32) -> 3 | P32: H
A33: 0 | B33: 0 | C33: 0 | D33: 1 | E33: 0 | F33: 0 | G33: 1 | H33: 1 | O33: =SUM(A33:N33) -> 3 | P33: G
A34: 0 | B34: 0 | C34: 0 | D34: 1 | E34: 1 | F34: 0 | G34: 1 | O34: =SUM(A34:N34) -> 3 | P34: F
A35: 0 | B35: 0 | C35: 0 | D35: 1 | E35: 1 | F35: 1 | O35: =SUM(A35:N35) -> 3 | P35: E
A36: 1 | B36: 0 | C36: 0 | D36: 1 | E36: 0 | F36: 0 | G36: 1 | O36: =SUM(A36:N36) -> 3 | P36: D
A37: 1 | B37: 0 | C37: 0 | D37: 1 | E37: 1 | O37: =SUM(A37:N37) -> 3 | P37: C
A38: 1 | B38: 1 | C38: 0 | D38: 1 | O38: =SUM(A38:N38) -> 3 | P38: B
A39: 1 | B39: 1 | C39: 1 | O39: =SUM(A39:N39) -> 3 | P39: A
A41: LoadDisplay.Count = 4
A42: Width[0] = 0.0
A43: Row 1 | E43: Row 2 | I43: Row 3 | M43: Row 4
A44: 1 | B44: 0 | C44: 0 | D44: 0 | E44: 1 | F44: 0 | G44: 0 | H44: 0 | I44: 1 | J44: 0 | K44: 0 | L44: 0 | M44: 1 | R44: H
...

Sheet Batch Display
B3: display area | D3: 98" x 197" | I3: Test
D4: =98*25.4 -> 2489.2 | E4: =197*25.4 -> 5003.8 | I4: =(D4-100)/3 -> 796.4 | K4: =(E4-360)/5 -> 928.76 | P4: 796.4 | R4: =(P4*P6)+(P5*(P6-1)) -> 2489.2
P5: 50
D6: 1024 | E6: 1752 | I6: 796.4 | J6: X | K6: 928.7 | P6: 3
D7: =D4/D6 -> 2.4308594 | E7: =E4/E6 -> 2.8560502 | I7: =I6/25.4 -> 31.354331 | K7: =K6/25.4 -> 36.562992 | N7: =25.4/16 -> 1.5875
C8: 345 | D8: =D4*(C8/1000) -> 858.774 | E8: =E4*(C8/1000) -> 1726.311 | S8: 796.4 | T8: =S8/25.4 -> 31.354331
D9: =((FLOOR(D8/8,1))+1)*8 -> 864 | E9: =((FLOOR(E8/8,1))+1)*8 -> 1728 | G9: =1920-E9 -> 192 | I9: =(I6*3)+100 -> 2489.2 | J9: =I9*0.35 -> 871.22 | T9: =FLOOR(T8,1) -> 31
D10: =((1080-D9)/2) -> 108 | T10: =T9*25.4 -> 787.4
T11: =S8-T10 -> 9 | U11: =T11/S13 -> 5.6692913
A12: 1920 | B12: 1080 | G12: Rectangle | H12: 5 x 0.5 x 0.35m | L12: Text | T12: =T11*10 -> 90
A13: 5004 | B13: 2490 | F13: =CEILING(((2200-1950)/2) *0.375,1) -> 47 | G13: =F13+128 -> 175 | H13: y1(Top) | I13: 23 | J13: x1(Left) | L13: =I13+5 -> 28 | M13: x1(Left) | N13: =G13+5 -> 180 | O13: y1(Top) | S13: =25.4*(1/16) -> 1.5875
A14: =A13*0.35 -> 1751.4 | B14: =B13*0.35 -> 871.5 | F14: =FLOOR(350*0.375,1) -> 131 | G14: 131 | H14: y2(Height) | I14: 187 | J14: x2(Width)
A15: =A12/A13 -> 0.38369305 | B15: =B12/B13 -> 0.43373494 | F15: =FLOOR(50*0.375,1) -> 18 | G15: =G13+150 -> 325 | H15: y1(Top) | I15: 23 | J15: x1(Left) | L15: =I15+5 -> 28 | M15: x1(Left) | N15: =G15+5 -> 330 | O15: y1(Top)
G16: 131 | H16: y2(Height) | I16: 187 | J16: x2(Width)
G17: =G15+150 -> 475 | H17: y1(Top) | I17: 23 | J17: x1(Left) | L17: =I17+5 -> 28 | M17: x1(Left) | N17: =G17+5 -> 480 | O17: y1(Top)
A18: 1800 | B18: 1000 | G18: 131 | H18: y2(Height) | I18: 187 | J18: x2(Width)
A19: =A18*0.375 -> 675 | B19: =B18*0.375 -> 375 | G19: =G17+150 -> 625 | H19: y1(Top) | I19: 23 | J19: x1(Left) | L19: =I19+5 -> 28 | M19: x1(Left) | N19: =G19+5 -> 630 | O19: y1(Top)
G20: 131 | H20: y2(Height) | I20: 187 | J20: x2(Width)
D21: =FLOOR(2200/350,1) -> 6 | E21: =(350*5) + ((5-1)*50) -> 1950 | G21: =G19+150 -> 775 | H21: y1(Top) | I21: 23 | J21: x1(Left) | L21: =I21+5 -> 28 | M21: x1(Left) | N21: =G21+5 -> 780 | O21: y1(Top)
G22: 131 | H22: y2(Height) | I22: 187 | J22: x2(Width)
A25: Left | B25: Top | G25: 2 x 1.8 x 1.0m | L25: Text
A26: 23 | B26: 128 | F26: =FLOOR((70*0.375),1) -> 26 | G26: =I13+I14+F26 -> 236 | H26: x1(Left) | I26: 156 | J26: y1(Top) | L26: =G26+5 -> 241 | N26: =I26+5 -> 161
G27: 675 | H27: x2(Width) | I27: 375 | J27: y2(Height)
G28: 236 | H28: x1(Left) | I28: 549 | J28: y1(Top) | L28: =G28+5 -> 241 | N28: =I28+5 -> 554
G29: 675 | H29: x2(Width) | I29: 375 | J29: y2(Height)
A31: =SUM(A33:A42) -> 4010 | B31: =5000-A31 -> 990 | C31: =FLOOR(A31*0.375,1) -> 1503 | D31: =C31+23 -> 1526
G32: 3 x 1.5 x 0.7m | L32: Text
A33: 500 | D33: Length | E33: 1500 | F33: =FLOOR(E33*0.375,1) -> 562 | G33: 938 | H33: x1(Left) | I33: 128 | J33: y1(Top) | L33: =G33+5 -> 943 | N33: =I33+5 -> 133
A34: 70 | D34: Width | E34: 700 | F34: =FLOOR(E34*0.375,1) -> 262 | G34: 562 | H34: x2(Width) | I34: 262 | J34: y2(Height)
A35: 1800 | D35: Width + Gap | E35: =E34+50 -> 750 | F35: =FLOOR(E35*0.375,1) -> 281 | G35: 938 | H35: x1(Left) | I35: =I33+281 -> 409 | J35: y1(Top) | L35: =G35+5 -> 943 | N35: =I35+5 -> 414
A36: 70 | G36: 562 | H36: x2(Width) | I36: 262 | J36: y2(Height)
A37: 1500 | G37: 938 | H37: x1(Left) | I37: =I35+281 -> 690 | J37: y1(Top) | L37: =G37+5 -> 943 | N37: =I37+5 -> 695
A38: 70 | G38: 562 | H38: x2(Width) | I38: 262 | J38: y2(Height)
G41: 5 x 0.9 x 0.4m | L41: Text
D42: Length | E42: 900 | F42: =FLOOR(E42*0.375,1) -> 337 | G42: 1526 | H42: x1(Left) | I42: 128 | J42: y1(Top) | L42: =G42+5 -> 1531 | N42: =I42+5 -> 133
D43: Width | E43: 400 | F43: =FLOOR(E43*0.375,1) -> 150 | G43: 337 | H43: x2(Width) | I43: 150 | J43: y2(Height)
D44: Width + Gap | E44: =E43+50 -> 450 | F44: =FLOOR(E44*0.375,1) -> 168 | G44: 1526 | H44: x1(Left) | I44: =I42+168 -> 296 | J44: y1(Top) | L44: =G44+5 -> 1531 | N44: =I44+5 -> 301
G45: 337 | H45: x2(Width) | I45: 150 | J45: y2(Height)
G46: 1526 | H46: x1(Left) | I46: =I44+168 -> 464 | J46: y1(Top) | L46: =G46+5 -> 1531 | N46: =I46+5 -> 469
G47: 337 | H47: x2(Width) | I47: 150 | J47: y2(Height)
...

Sheet Analog
A3: Analog Scaling | N3: Modes
A4: 0-10V | N4: Loading | O4: Single
A5: Volts | O5: Multi
A6: 0 | B6: 10 | N6: Batch Furnace
A7: Raw Value | N7: Auto
A8: 0 | B8: 8192 | N8: Single
A9: Actual Speed m/min | N9: Pair
A10: 0 | B10: 15 | N10: Fours
A11: Record Raw Value and actual speed of external equipment into permanent variables. Overwrite every time it is recorded. | N11: Offline Batching
A12: e.g. | N12: Continuous Furnace
A13: 10m/min | B13: 5461 | N13: Offline loading
A14: Use Actual speed to compare to 50m/min frequency of CRE.
A15: Scale values so that Analog Raw value equates to Frequency. | N15: Furnace Change
N17: Furnace Clear
A18: Use e.g. ScalePerm.CREScale | N18: Pulse
N19: On
A20: Create .SpeedAnalog to use in place of Speeds.Speed**** when using Analog following.
N21: Pause
A22: 0HZ | B22: 50Hz
A23: 0 | B23: 500
E28: 0 | G28: 52
A29: 5461 | B29: 8192 | C29: =B29*0.8 -> 6553.6 | E29: 0 | G29: 50
B30: =A29/B29 -> 0.66662598
G31: =G29/G28 -> 0.96153846
B32: =A29/10 -> 546.1 | C32: =B32*50 -> 27305 | D32: =C32*(52/50) -> 28397.2
D33: 5461
B36: 4 | C36: 20
B37: 0 | C37: 20
B41: 8192 | C41: 15 | D41: 50 | E41: =D41/C41 -> 3.3333333 | F41: =B41*E41 -> 27306.667
B44: 5461 | C44: 10 | D44: 50 | E44: =((B44/C44)*D44)*0.8 -> 21844
B45: 5461 | C45: 10 | D45: 40 | E45: =((B45/C45)*D45) -> 21844

Sheet Ashton FB
A1: TrackBit Function Block
A3: VAR_INPUT | E3: VAR_OUTPUT | I3: VAR
C4: Description | G4: Description | K4: Description
A5: FixedIN.Control | B5: BOOL | C5: Control Circuit ON | E5: Active | F5: BOOL | G5: Track Bit is currently Active | I5: DelayTON | J5: TON | K5: Time Delay used either for Timeout or Track bit delay
A6: FixedIN.ESClearing | B6: BOOL | C6: During Estop Recovery | E6: Done | F6: BOOL | G6: Track Bit Done conditions are TRUE | I6: INITBlock | J6: USINT | K6: Use to block processing of End Condition for 2 scans
A7: RunBlock | B7: BOOL | C7: Set high to disable Conveyor Run Output, iF OFF conveyor run signal will be TRUE. | E7: Disp | F7: Display_enum | G7: Visualisation control for Track Bit | I7: TimeoutACKLatch | J7: BOOL | K7: Latch on TimeoutACK while TrackBit active
A8: SolBlock | B8: BOOL | C8: Set high to disable Solenoid activation, if OFF solenoid out signal will be TRUE. | E8: ESDisp | F8: Display_enum | G8: Visualisation control for Track Bit during Estop Recovery
A9: Analog | B9: USINT | C9: Analog Selection, 0 = No Analog | E9: RunOUT | F9: BOOL | G9: Conveyor Run Output
A10: Speed | B10: REAL | C10: Speed Reference Input. | E10: SolOUT | F10: BOOL | G10: Solenoid activation output. Will always be TRUE. Negate as required.
A11: SpeedAnalog | B11: REAL | C11: Analog Speed Reference | E11: SpeedOUT | F11: REAL | G11: Conveyor Run speed reference
A12: SpeedMatchEN | B12: BOOL | C12: Speed Match Enable, speed has to match speed of another conveyor | E12: TimeoutOUT | F12: BOOL | G12: Timeout delay has timed out
A13: SpeedMatch | B13: REAL | C13: Speed Match reference
A14: TimeoutBlock | B14: BOOL | C14: Block for timeout, if OFF timeout will continue
A15: TimeoutEN | B15: BOOL | C15: Enable timeout for this TrackBit
A16: TrackDelayEN | B16: BOOL | C16: Enable Delay for this TrackBit, where end condition is delay done.
A17: DelayPT | B17: UDINT | C17: Preset time for timeout
A18: TimeoutACK | B18: BOOL | C18: Timeout Acknowledge
A19: EndIN | B19: BOOL | C19: End of Tracking Bit Condition
A20: DoneIN | B20: BOOL | C20: Early End of Tracking Bit Condition
A21: EndCondition | B21: USINT | C21: End Condition type, EDGEPOS, EDGENEG, NO, NC.
A25: TrackingSection Function Block | E25: VAR_OUTPUT | I25: VAR
A26: VAR_INPUT | G26: Description | K26: Description
C27: Description | E27: Busy | F27: BOOL | G27: Tracking section is currently Busy | I27: CurrentTime | J27: TIME | K27: Current captured time
A28: Blocks | B28: ARRAY[0..12]OF BOOL | C28: Block conditions of Following section | E28: Blocked | F28: BOOL | G28: Block conditions for following section is active | I28: PreviousTime | J28: TIME | K28: Previous captured time
A29: Clear | B29: BOOL | C29: Control to be selected for clearing during Estop Recovery | E29: BusyDisp | F29: Display_enum | G29: Visualisation control for Mimic screen | I29: ElapsedTime | J29: UDINT | K29: Elapsed/Cycle time
A30: ResES | B30: BOOL | C30: Reset Index during Estop recovery | E30: Index | F30: USINT | G30: Index for TrackBits CASE statement | I30: i | J30: USINT | K30: Index for Blocks[0..12]
A31: ResMan | B31: BOOL | C31: Reset Index from Mimic screen with greater than OPERATOR level | E31: Width | F31: REAL | G31: Data Tracking
A32: IndexIN | B32: USINT | C32: New Index Value | E32: Length | F32: REAL | G32: Data Tracking
A33: BlockInhib | B33: BOOL | C33: Override Block conditions, e.g. for early restart. | E33: Longest | F33: REAL | G33: Data Tracking
A34: WidthIN | B34: REAL | C34: Data Tracking | E34: RowBlock | F34: BOOL | G34: Process Tracking
A35: LengthIN | B35: REAL | C35: Data Tracking | E35: Change | F35: BOOL | G35: Process Tracking
A36: LongestIN | B36: REAL | C36: Data Tracking | E36: ArrissUpper | F36: BOOL | G36: Process Tracking
A37: RowBlockIN | B37: BOOL | C37: Process Tracking | E37: ArrissLower | F37: BOOL | G37: Process Tracking
A38: ChangeIN | B38: BOOL | C38: Process Tracking | E38: EdgeDelete | F38: BOOL | G38: Process Tracking
A39: ArrissUpperIN | B39: BOOL | C39: Process Tracking | E39: VerticalBelt | F39: BOOL | G39: Process Tracking
A40: ArrissLowerIN | B40: BOOL | C40: Process Tracking | E40: Cycle | F40: REAL | G40: Calculated cycle time
A41: EdgeDeleteIN | B41: BOOL | C41: Process Tracking | E41: FixedOUT.Control | F41: BOOL | G41: To FixedIN.Control for each TrackBit
A42: VerticalBeltIN | B42: BOOL | C42: Process Tracking | E42: FixedOUT.ESClearing | F42: BOOL | G42: To FixedIN.ESClearing for each TrackBit
A43: ControlIN | B43: BOOL | C43: Control.Achieved
A46: ARRAY[0..12]OF BOOL
...
